<?xml version="1.0"?>
<robot xmlns:xacro="http://www.ros.org/wiki/xacro">

    <xacro:include filename="color.urdf.xacro" />
    <xacro:include filename="inertia.urdf.xacro" />

    <link name="base_link">
    </link>

    <joint name="base_footprint_joint" type="fixed">
        <parent link="base_link"/>
        <child link="base_footprint"/>
        <origin xyz="0 0 0" rpy="0 0 0"/>
    </joint>

    <link name="base_footprint">
    </link>

    <joint name="chassis_joint" type="fixed">
        <parent link="base_link" />
        <child link="chassis_link" />
        <origin xyz="-0.3 0 0" rpy="0 0 0" />
    </joint>

    <link name="chassis_link">
        <visual>
            <origin xyz="0.3 0 0.075" rpy="0 0 0" />
            <geometry>
                <box size="0.6 0.3 0.15" />
            </geometry>
            <material name="white" />
        </visual>
        <collision>
            <origin xyz="0.3 0 0.075" rpy="0 0 0" />
            <geometry>
                <box size="0.6 0.3 0.15" />
            </geometry>
        </collision>
        <xacro:inertial_box mass="10.0" x="0.6" y="0.3" z="0.15">
            <origin xyz="0.3 0 0.075" rpy="0 0 0" />
        </xacro:inertial_box>
    </link>

    <gazebo reference="chassis_link">
        <material>Gazebo/White</material>
    </gazebo>

    <joint name="left_rear_wheel_joint" type="continuous">
        <parent link="chassis_link" />
        <child link="left_rear_wheel_link" />
        <origin xyz="0.15 0.15 0" rpy="-${pi/2} 0 0" />
        <axis xyz="0 0 1" />
    </joint>

    <link name="left_rear_wheel_link">
        <visual>
            <origin xyz="0 0 0" rpy="0 0 0" />
            <geometry>
                <cylinder radius="0.075" length="0.0375" />
            </geometry>
            <material name="black" />
        </visual>
        <collision>
            <origin xyz="0 0 0" rpy="0 0 0" />
            <geometry>
                <cylinder radius="0.075" length="0.0375" />
            </geometry>
        </collision>
        <xacro:inertial_cylinder mass="1.0" radius="0.075" length="0.0375">
            <origin xyz="0 0 0" rpy="0 0 0" />
        </xacro:inertial_cylinder>
    </link>

    <gazebo reference="left_rear_wheel_link">
        <material>Gazebo/Black</material>
    </gazebo>

    <joint name="right_rear_wheel_joint" type="continuous">
        <parent link="chassis_link" />
        <child link="right_rear_wheel_link" />
        <origin xyz="0.15 -0.15 0" rpy="-${pi/2} 0 0" />
        <axis xyz="0 0 1" />
    </joint>

    <link name="right_rear_wheel_link">
        <visual>
            <origin xyz="0 0 0" rpy="0 0 0" />
            <geometry>
                <cylinder radius="0.075" length="0.0375" />
            </geometry>
            <material name="black" />
        </visual>
        <collision>
            <origin xyz="0 0 0" rpy="0 0 0" />
            <geometry>
                <cylinder radius="0.075" length="0.0375" />
            </geometry>
        </collision>
        <xacro:inertial_cylinder mass="1.0" radius="0.075" length="0.0375">
            <origin xyz="0 0 0" rpy="0 0 0" />
        </xacro:inertial_cylinder>
    </link>

    <gazebo reference="right_rear_wheel_link">
        <material>Gazebo/Black</material>
    </gazebo>

    <joint name="front_caster_joint" type="fixed">
        <parent link="chassis_link" />
        <child link="front_caster_link" />
        <origin xyz="0.45 0 0" rpy="0 0 0" />
    </joint>
    <link name="front_caster_link">
        <visual>
            <origin xyz="0 0 0" rpy="0 0 0" />
            <geometry>
                <sphere radius="0.075" />
            </geometry>
            <material name="black" />
        </visual>
        <collision>
            <origin xyz="0 0 0" rpy="0 0 0" />
            <geometry>
                <sphere radius="0.075" />
            </geometry>
        </collision>
        <xacro:inertial_sphere mass="0.5" radius="0.075">
            <origin xyz="0 0 0" rpy="0 0 0" />
        </xacro:inertial_sphere>
    </link>
    <gazebo reference="front_caster_link">
        <material>Gazebo/Black</material>
        <mu1 value="0.001" />
        <mu2 value="0.001" />
    </gazebo>

</robot>